<?xml version="1.0" encoding="UTF-8"?>
<!-- Generated by org.testng.reporters.JUnitReportReporter -->
<testsuite hostname="H4877CC0001" failures="1" tests="4" name="ar.com.bna.digitaltest.testcases.Login2Test" time="178.606" errors="0" timestamp="2025-08-25T12:12:02 GMT-03:00" skipped="3">
  <testcase classname="ar.com.bna.digitaltest.testcases.Login2Test" name="enterValidCredentialsAndLogin" time="39.860">
    <failure message="expected [false] but found [true]" type="java.lang.AssertionError">
      <![CDATA[java.lang.AssertionError: expected [false] but found [true]
at org.testng.Assert.fail(Assert.java:99)
at org.testng.Assert.failNotEquals(Assert.java:1037)
at org.testng.Assert.assertFalse(Assert.java:67)
at org.testng.Assert.assertFalse(Assert.java:77)
at ar.com.bna.digitaltest.testcases.Login2Test.enterValidCredentialsAndLogin(Login2Test.java:22)
at java.base/jdk.internal.reflect.DirectMethodHandleAccessor.invoke(DirectMethodHandleAccessor.java:103)
at java.base/java.lang.reflect.Method.invoke(Method.java:580)
at org.testng.internal.MethodInvocationHelper.invokeMethod(MethodInvocationHelper.java:133)
at org.testng.internal.TestInvoker.invokeMethod(TestInvoker.java:598)
at org.testng.internal.TestInvoker.retryFailed(TestInvoker.java:213)
at org.testng.internal.MethodRunner.runInSequence(MethodRunner.java:58)
at org.testng.internal.TestInvoker$MethodInvocationAgent.invoke(TestInvoker.java:824)
at org.testng.internal.TestInvoker.invokeTestMethods(TestInvoker.java:146)
at org.testng.internal.TestMethodWorker.invokeTestMethods(TestMethodWorker.java:146)
at org.testng.internal.TestMethodWorker.run(TestMethodWorker.java:128)
at java.base/java.util.ArrayList.forEach(ArrayList.java:1597)
at org.testng.TestRunner.privateRun(TestRunner.java:794)
at org.testng.TestRunner.run(TestRunner.java:596)
at org.testng.SuiteRunner.runTest(SuiteRunner.java:377)
at org.testng.SuiteRunner.runSequentially(SuiteRunner.java:371)
at org.testng.SuiteRunner.privateRun(SuiteRunner.java:332)
at org.testng.SuiteRunner.run(SuiteRunner.java:276)
at org.testng.SuiteRunnerWorker.runSuite(SuiteRunnerWorker.java:53)
at org.testng.SuiteRunnerWorker.run(SuiteRunnerWorker.java:96)
at org.testng.TestNG.runSuitesSequentially(TestNG.java:1212)
at org.testng.TestNG.runSuitesLocally(TestNG.java:1134)
at org.testng.TestNG.runSuites(TestNG.java:1063)
at org.testng.TestNG.run(TestNG.java:1031)
at org.testng.remote.AbstractRemoteTestNG.run(AbstractRemoteTestNG.java:115)
at org.testng.remote.RemoteTestNG.initAndRun(RemoteTestNG.java:293)
at org.testng.remote.RemoteTestNG.main(RemoteTestNG.java:91)
]]>
    </failure>
  </testcase> <!-- enterValidCredentialsAndLogin -->
  <system-out/>
  <testcase classname="ar.com.bna.digitaltest.testcases.Login2Test" name="enterValidCredentialsAndLogin" time="61.753">
    <skipped/>
  </testcase> <!-- enterValidCredentialsAndLogin -->
  <system-out/>
  <testcase classname="ar.com.bna.digitaltest.testcases.Login2Test" name="enterValidCredentialsAndLogin" time="32.389">
    <skipped/>
  </testcase> <!-- enterValidCredentialsAndLogin -->
  <system-out/>
  <testcase classname="ar.com.bna.digitaltest.testcases.Login2Test" name="enterValidCredentialsAndLogin" time="44.604">
    <skipped/>
  </testcase> <!-- enterValidCredentialsAndLogin -->
  <system-out/>
</testsuite> <!-- ar.com.bna.digitaltest.testcases.Login2Test -->
